[16/Jun/2022 09:03:40] "GET / HTTP/1.1" 200 2676
[16/Jun/2022 09:03:47] "GET / HTTP/1.1" 200 2676
Performing system checks...

________________scrape_request.html
System check identified no issues (0 silenced).
June 16, 2022 - 08:43:02
Django version 3.0.7, using settings 'amazon_scraper.settings'
Starting development server at http://0.0.0.0:8080/
Quit the server with CONTROL-C.
Performing system checks...

________________scrape_request.html
System check identified no issues (0 silenced).
June 16, 2022 - 09:18:34
Django version 3.0.7, using settings 'amazon_scraper.settings'
Starting development server at http://0.0.0.0:8080/
Quit the server with CONTROL-C.
Exception in thread django-main-thread:
Traceback (most recent call last):
  File "/usr/lib64/python3.6/threading.py", line 916, in _bootstrap_inner
    self.run()
  File "/usr/lib64/python3.6/threading.py", line 864, in run
    self._target(*self._args, **self._kwargs)
  File "/root/.local/lib/python3.6/site-packages/django/utils/autoreload.py", line 53, in wrapper
    fn(*args, **kwargs)
  File "/root/.local/lib/python3.6/site-packages/django/core/management/commands/runserver.py", line 117, in inner_run
    self.check(display_num_errors=True)
  File "/root/.local/lib/python3.6/site-packages/django/core/management/base.py", line 395, in check
    include_deployment_checks=include_deployment_checks,
  File "/root/.local/lib/python3.6/site-packages/django/core/management/base.py", line 382, in _run_checks
    return checks.run_checks(**kwargs)
  File "/root/.local/lib/python3.6/site-packages/django/core/checks/registry.py", line 72, in run_checks
    new_errors = check(app_configs=app_configs)
  File "/root/.local/lib/python3.6/site-packages/django/core/checks/urls.py", line 13, in check_url_config
    return check_resolver(resolver)
  File "/root/.local/lib/python3.6/site-packages/django/core/checks/urls.py", line 23, in check_resolver
    return check_method()
  File "/root/.local/lib/python3.6/site-packages/django/urls/resolvers.py", line 407, in check
    for pattern in self.url_patterns:
  File "/root/.local/lib/python3.6/site-packages/django/utils/functional.py", line 48, in __get__
    res = instance.__dict__[self.name] = self.func(instance)
  File "/root/.local/lib/python3.6/site-packages/django/urls/resolvers.py", line 588, in url_patterns
    patterns = getattr(self.urlconf_module, "urlpatterns", self.urlconf_module)
  File "/root/.local/lib/python3.6/site-packages/django/utils/functional.py", line 48, in __get__
    res = instance.__dict__[self.name] = self.func(instance)
  File "/root/.local/lib/python3.6/site-packages/django/urls/resolvers.py", line 581, in urlconf_module
    return import_module(self.urlconf_name)
  File "/usr/lib64/python3.6/importlib/__init__.py", line 126, in import_module
    return _bootstrap._gcd_import(name[level:], package, level)
  File "<frozen importlib._bootstrap>", line 994, in _gcd_import
  File "<frozen importlib._bootstrap>", line 971, in _find_and_load
  File "<frozen importlib._bootstrap>", line 955, in _find_and_load_unlocked
  File "<frozen importlib._bootstrap>", line 665, in _load_unlocked
  File "<frozen importlib._bootstrap_external>", line 678, in exec_module
  File "<frozen importlib._bootstrap>", line 219, in _call_with_frames_removed
  File "/root/aktool/amazon_scraper/urls.py", line 12, in <module>
    ] + static(settings.MEDIA_URL, document_root=settings.MEDIA_ROOT) + static(settings.STATIC_URL, document_root=settings.STATIC_ROOT)
  File "/root/.local/lib/python3.6/site-packages/django/urls/conf.py", line 34, in include
    urlconf_module = import_module(urlconf_module)
  File "/usr/lib64/python3.6/importlib/__init__.py", line 126, in import_module
    return _bootstrap._gcd_import(name[level:], package, level)
  File "<frozen importlib._bootstrap>", line 994, in _gcd_import
  File "<frozen importlib._bootstrap>", line 971, in _find_and_load
  File "<frozen importlib._bootstrap>", line 955, in _find_and_load_unlocked
  File "<frozen importlib._bootstrap>", line 665, in _load_unlocked
  File "<frozen importlib._bootstrap_external>", line 678, in exec_module
  File "<frozen importlib._bootstrap>", line 219, in _call_with_frames_removed
  File "/root/aktool/main/urls.py", line 3, in <module>
    from . import views
  File "/root/aktool/main/views.py", line 11, in <module>
    from .forms import SignupForm, UserUpdateForm, RequestTextForm, RequestCsvForm, PasswordChangeForm
  File "/root/aktool/main/forms.py", line 10, in <module>
    class UserUpdateForm(forms.ModelForm):
  File "/root/.local/lib/python3.6/site-packages/django/forms/models.py", line 267, in __new__
    raise FieldError(message)
django.core.exceptions.FieldError: Unknown field(s) (api_type) specified for User

Performing system checks...

Performing system checks...

________________scrape_request.html
System check identified no issues (0 silenced).
June 28, 2022 - 21:59:11
Django version 3.0.7, using settings 'amazon_scraper.settings'
Starting development server at http://0.0.0.0:8080/
Quit the server with CONTROL-C.
Performing system checks...

________________scrape_request.html
System check identified no issues (0 silenced).
June 28, 2022 - 21:59:50
Django version 3.0.7, using settings 'amazon_scraper.settings'
Starting development server at http://0.0.0.0:8080/
Quit the server with CONTROL-C.
Performing system checks...

________________scrape_request.html
System check identified no issues (0 silenced).
June 28, 2022 - 21:59:55
Django version 3.0.7, using settings 'amazon_scraper.settings'
Starting development server at http://0.0.0.0:8080/
Quit the server with CONTROL-C.
Exception in thread django-main-thread:
Traceback (most recent call last):
  File "/usr/lib64/python3.6/threading.py", line 916, in _bootstrap_inner
    self.run()
  File "/usr/lib64/python3.6/threading.py", line 864, in run
    self._target(*self._args, **self._kwargs)
  File "/root/.local/lib/python3.6/site-packages/django/utils/autoreload.py", line 53, in wrapper
    fn(*args, **kwargs)
  File "/root/.local/lib/python3.6/site-packages/django/core/management/commands/runserver.py", line 117, in inner_run
    self.check(display_num_errors=True)
  File "/root/.local/lib/python3.6/site-packages/django/core/management/base.py", line 395, in check
    include_deployment_checks=include_deployment_checks,
  File "/root/.local/lib/python3.6/site-packages/django/core/management/base.py", line 382, in _run_checks
    return checks.run_checks(**kwargs)
  File "/root/.local/lib/python3.6/site-packages/django/core/checks/registry.py", line 72, in run_checks
    new_errors = check(app_configs=app_configs)
  File "/root/.local/lib/python3.6/site-packages/django/core/checks/urls.py", line 13, in check_url_config
    return check_resolver(resolver)
  File "/root/.local/lib/python3.6/site-packages/django/core/checks/urls.py", line 23, in check_resolver
    return check_method()
  File "/root/.local/lib/python3.6/site-packages/django/urls/resolvers.py", line 407, in check
    for pattern in self.url_patterns:
  File "/root/.local/lib/python3.6/site-packages/django/utils/functional.py", line 48, in __get__
    res = instance.__dict__[self.name] = self.func(instance)
  File "/root/.local/lib/python3.6/site-packages/django/urls/resolvers.py", line 588, in url_patterns
    patterns = getattr(self.urlconf_module, "urlpatterns", self.urlconf_module)
  File "/root/.local/lib/python3.6/site-packages/django/utils/functional.py", line 48, in __get__
    res = instance.__dict__[self.name] = self.func(instance)
  File "/root/.local/lib/python3.6/site-packages/django/urls/resolvers.py", line 581, in urlconf_module
    return import_module(self.urlconf_name)
  File "/usr/lib64/python3.6/importlib/__init__.py", line 126, in import_module
    return _bootstrap._gcd_import(name[level:], package, level)
  File "<frozen importlib._bootstrap>", line 994, in _gcd_import
  File "<frozen importlib._bootstrap>", line 971, in _find_and_load
  File "<frozen importlib._bootstrap>", line 955, in _find_and_load_unlocked
  File "<frozen importlib._bootstrap>", line 665, in _load_unlocked
  File "<frozen importlib._bootstrap_external>", line 678, in exec_module
  File "<frozen importlib._bootstrap>", line 219, in _call_with_frames_removed
  File "/root/aktool/amazon_scraper/urls.py", line 12, in <module>
    ] + static(settings.MEDIA_URL, document_root=settings.MEDIA_ROOT) + static(settings.STATIC_URL, document_root=settings.STATIC_ROOT)
  File "/root/.local/lib/python3.6/site-packages/django/urls/conf.py", line 34, in include
    urlconf_module = import_module(urlconf_module)
  File "/usr/lib64/python3.6/importlib/__init__.py", line 126, in import_module
    return _bootstrap._gcd_import(name[level:], package, level)
  File "<frozen importlib._bootstrap>", line 994, in _gcd_import
  File "<frozen importlib._bootstrap>", line 971, in _find_and_load
  File "<frozen importlib._bootstrap>", line 955, in _find_and_load_unlocked
  File "<frozen importlib._bootstrap>", line 665, in _load_unlocked
  File "<frozen importlib._bootstrap_external>", line 678, in exec_module
  File "<frozen importlib._bootstrap>", line 219, in _call_with_frames_removed
  File "/root/aktool/main/urls.py", line 3, in <module>
    from . import views
  File "/root/aktool/main/views.py", line 11, in <module>
    from .forms import SignupForm, UserUpdateForm, RequestTextForm, RequestCsvForm, PasswordChangeForm
  File "/root/aktool/main/forms.py", line 10, in <module>
    class UserUpdateForm(forms.ModelForm):
  File "/root/.local/lib/python3.6/site-packages/django/forms/models.py", line 267, in __new__
    raise FieldError(message)
django.core.exceptions.FieldError: Unknown field(s) (market_placeasdas) specified for User

Performing system checks...

Exception in thread django-main-thread:
Traceback (most recent call last):
  File "/usr/lib64/python3.6/threading.py", line 916, in _bootstrap_inner
    self.run()
  File "/usr/lib64/python3.6/threading.py", line 864, in run
    self._target(*self._args, **self._kwargs)
  File "/root/.local/lib/python3.6/site-packages/django/utils/autoreload.py", line 53, in wrapper
    fn(*args, **kwargs)
  File "/root/.local/lib/python3.6/site-packages/django/core/management/commands/runserver.py", line 117, in inner_run
    self.check(display_num_errors=True)
  File "/root/.local/lib/python3.6/site-packages/django/core/management/base.py", line 395, in check
    include_deployment_checks=include_deployment_checks,
  File "/root/.local/lib/python3.6/site-packages/django/core/management/base.py", line 382, in _run_checks
    return checks.run_checks(**kwargs)
  File "/root/.local/lib/python3.6/site-packages/django/core/checks/registry.py", line 72, in run_checks
    new_errors = check(app_configs=app_configs)
  File "/root/.local/lib/python3.6/site-packages/django/core/checks/urls.py", line 13, in check_url_config
    return check_resolver(resolver)
  File "/root/.local/lib/python3.6/site-packages/django/core/checks/urls.py", line 23, in check_resolver
    return check_method()
  File "/root/.local/lib/python3.6/site-packages/django/urls/resolvers.py", line 407, in check
    for pattern in self.url_patterns:
  File "/root/.local/lib/python3.6/site-packages/django/utils/functional.py", line 48, in __get__
    res = instance.__dict__[self.name] = self.func(instance)
  File "/root/.local/lib/python3.6/site-packages/django/urls/resolvers.py", line 588, in url_patterns
    patterns = getattr(self.urlconf_module, "urlpatterns", self.urlconf_module)
  File "/root/.local/lib/python3.6/site-packages/django/utils/functional.py", line 48, in __get__
    res = instance.__dict__[self.name] = self.func(instance)
  File "/root/.local/lib/python3.6/site-packages/django/urls/resolvers.py", line 581, in urlconf_module
    return import_module(self.urlconf_name)
  File "/usr/lib64/python3.6/importlib/__init__.py", line 126, in import_module
    return _bootstrap._gcd_import(name[level:], package, level)
  File "<frozen importlib._bootstrap>", line 994, in _gcd_import
  File "<frozen importlib._bootstrap>", line 971, in _find_and_load
  File "<frozen importlib._bootstrap>", line 955, in _find_and_load_unlocked
  File "<frozen importlib._bootstrap>", line 665, in _load_unlocked
  File "<frozen importlib._bootstrap_external>", line 678, in exec_module
  File "<frozen importlib._bootstrap>", line 219, in _call_with_frames_removed
  File "/root/aktool/amazon_scraper/urls.py", line 12, in <module>
    ] + static(settings.MEDIA_URL, document_root=settings.MEDIA_ROOT) + static(settings.STATIC_URL, document_root=settings.STATIC_ROOT)
  File "/root/.local/lib/python3.6/site-packages/django/urls/conf.py", line 34, in include
    urlconf_module = import_module(urlconf_module)
  File "/usr/lib64/python3.6/importlib/__init__.py", line 126, in import_module
    return _bootstrap._gcd_import(name[level:], package, level)
  File "<frozen importlib._bootstrap>", line 994, in _gcd_import
  File "<frozen importlib._bootstrap>", line 971, in _find_and_load
  File "<frozen importlib._bootstrap>", line 955, in _find_and_load_unlocked
  File "<frozen importlib._bootstrap>", line 665, in _load_unlocked
  File "<frozen importlib._bootstrap_external>", line 678, in exec_module
  File "<frozen importlib._bootstrap>", line 219, in _call_with_frames_removed
  File "/root/aktool/main/urls.py", line 3, in <module>
    from . import views
  File "/root/aktool/main/views.py", line 11, in <module>
    from .forms import SignupForm, UserUpdateForm, RequestTextForm, RequestCsvForm, PasswordChangeForm
  File "/root/aktool/main/forms.py", line 10, in <module>
    class UserUpdateForm(forms.ModelForm):
  File "/root/.local/lib/python3.6/site-packages/django/forms/models.py", line 267, in __new__
    raise FieldError(message)
django.core.exceptions.FieldError: Unknown field(s) (api_type) specified for User

Performing system checks...

Performing system checks...

________________scrape_request.html
System check identified no issues (0 silenced).
June 28, 2022 - 22:15:37
Django version 3.0.7, using settings 'amazon_scraper.settings'
Starting development server at http://0.0.0.0:8080/
Quit the server with CONTROL-C.
Exception in thread django-main-thread:
Traceback (most recent call last):
  File "/usr/lib64/python3.6/threading.py", line 916, in _bootstrap_inner
    self.run()
  File "/usr/lib64/python3.6/threading.py", line 864, in run
    self._target(*self._args, **self._kwargs)
  File "/root/.local/lib/python3.6/site-packages/django/utils/autoreload.py", line 53, in wrapper
    fn(*args, **kwargs)
  File "/root/.local/lib/python3.6/site-packages/django/core/management/commands/runserver.py", line 117, in inner_run
    self.check(display_num_errors=True)
  File "/root/.local/lib/python3.6/site-packages/django/core/management/base.py", line 395, in check
    include_deployment_checks=include_deployment_checks,
  File "/root/.local/lib/python3.6/site-packages/django/core/management/base.py", line 382, in _run_checks
    return checks.run_checks(**kwargs)
  File "/root/.local/lib/python3.6/site-packages/django/core/checks/registry.py", line 72, in run_checks
    new_errors = check(app_configs=app_configs)
  File "/root/.local/lib/python3.6/site-packages/django/core/checks/urls.py", line 13, in check_url_config
    return check_resolver(resolver)
  File "/root/.local/lib/python3.6/site-packages/django/core/checks/urls.py", line 23, in check_resolver
    return check_method()
  File "/root/.local/lib/python3.6/site-packages/django/urls/resolvers.py", line 407, in check
    for pattern in self.url_patterns:
  File "/root/.local/lib/python3.6/site-packages/django/utils/functional.py", line 48, in __get__
    res = instance.__dict__[self.name] = self.func(instance)
  File "/root/.local/lib/python3.6/site-packages/django/urls/resolvers.py", line 588, in url_patterns
    patterns = getattr(self.urlconf_module, "urlpatterns", self.urlconf_module)
  File "/root/.local/lib/python3.6/site-packages/django/utils/functional.py", line 48, in __get__
    res = instance.__dict__[self.name] = self.func(instance)
  File "/root/.local/lib/python3.6/site-packages/django/urls/resolvers.py", line 581, in urlconf_module
    return import_module(self.urlconf_name)
  File "/usr/lib64/python3.6/importlib/__init__.py", line 126, in import_module
    return _bootstrap._gcd_import(name[level:], package, level)
  File "<frozen importlib._bootstrap>", line 994, in _gcd_import
  File "<frozen importlib._bootstrap>", line 971, in _find_and_load
  File "<frozen importlib._bootstrap>", line 955, in _find_and_load_unlocked
  File "<frozen importlib._bootstrap>", line 665, in _load_unlocked
  File "<frozen importlib._bootstrap_external>", line 678, in exec_module
  File "<frozen importlib._bootstrap>", line 219, in _call_with_frames_removed
  File "/root/aktool/amazon_scraper/urls.py", line 12, in <module>
    ] + static(settings.MEDIA_URL, document_root=settings.MEDIA_ROOT) + static(settings.STATIC_URL, document_root=settings.STATIC_ROOT)
  File "/root/.local/lib/python3.6/site-packages/django/urls/conf.py", line 34, in include
    urlconf_module = import_module(urlconf_module)
  File "/usr/lib64/python3.6/importlib/__init__.py", line 126, in import_module
    return _bootstrap._gcd_import(name[level:], package, level)
  File "<frozen importlib._bootstrap>", line 994, in _gcd_import
  File "<frozen importlib._bootstrap>", line 971, in _find_and_load
  File "<frozen importlib._bootstrap>", line 955, in _find_and_load_unlocked
  File "<frozen importlib._bootstrap>", line 665, in _load_unlocked
  File "<frozen importlib._bootstrap_external>", line 678, in exec_module
  File "<frozen importlib._bootstrap>", line 219, in _call_with_frames_removed
  File "/root/aktool/main/urls.py", line 8, in <module>
    path('', views.Login.as_view(), name = 'login'),
AttributeError: module 'main.views' has no attribute 'Login'

Performing system checks...

Performing system checks...

________________scrape_request.html
System check identified no issues (0 silenced).
June 29, 2022 - 04:01:21
Django version 3.0.7, using settings 'amazon_scraper.settings'
Starting development server at http://0.0.0.0:8080/
Quit the server with CONTROL-C.
Exception in thread django-main-thread:
Traceback (most recent call last):
  File "/usr/lib64/python3.6/threading.py", line 916, in _bootstrap_inner
    self.run()
  File "/usr/lib64/python3.6/threading.py", line 864, in run
    self._target(*self._args, **self._kwargs)
  File "/root/.local/lib/python3.6/site-packages/django/utils/autoreload.py", line 53, in wrapper
    fn(*args, **kwargs)
  File "/root/.local/lib/python3.6/site-packages/django/core/management/commands/runserver.py", line 117, in inner_run
    self.check(display_num_errors=True)
  File "/root/.local/lib/python3.6/site-packages/django/core/management/base.py", line 395, in check
    include_deployment_checks=include_deployment_checks,
  File "/root/.local/lib/python3.6/site-packages/django/core/management/base.py", line 382, in _run_checks
    return checks.run_checks(**kwargs)
  File "/root/.local/lib/python3.6/site-packages/django/core/checks/registry.py", line 72, in run_checks
    new_errors = check(app_configs=app_configs)
  File "/root/.local/lib/python3.6/site-packages/django/core/checks/urls.py", line 13, in check_url_config
    return check_resolver(resolver)
  File "/root/.local/lib/python3.6/site-packages/django/core/checks/urls.py", line 23, in check_resolver
    return check_method()
  File "/root/.local/lib/python3.6/site-packages/django/urls/resolvers.py", line 407, in check
    for pattern in self.url_patterns:
  File "/root/.local/lib/python3.6/site-packages/django/utils/functional.py", line 48, in __get__
    res = instance.__dict__[self.name] = self.func(instance)
  File "/root/.local/lib/python3.6/site-packages/django/urls/resolvers.py", line 588, in url_patterns
    patterns = getattr(self.urlconf_module, "urlpatterns", self.urlconf_module)
  File "/root/.local/lib/python3.6/site-packages/django/utils/functional.py", line 48, in __get__
    res = instance.__dict__[self.name] = self.func(instance)
  File "/root/.local/lib/python3.6/site-packages/django/urls/resolvers.py", line 581, in urlconf_module
    return import_module(self.urlconf_name)
  File "/usr/lib64/python3.6/importlib/__init__.py", line 126, in import_module
    return _bootstrap._gcd_import(name[level:], package, level)
  File "<frozen importlib._bootstrap>", line 994, in _gcd_import
  File "<frozen importlib._bootstrap>", line 971, in _find_and_load
  File "<frozen importlib._bootstrap>", line 955, in _find_and_load_unlocked
  File "<frozen importlib._bootstrap>", line 665, in _load_unlocked
  File "<frozen importlib._bootstrap_external>", line 678, in exec_module
  File "<frozen importlib._bootstrap>", line 219, in _call_with_frames_removed
  File "/root/aktool/amazon_scraper/urls.py", line 12, in <module>
    ] + static(settings.MEDIA_URL, document_root=settings.MEDIA_ROOT) + static(settings.STATIC_URL, document_root=settings.STATIC_ROOT)
  File "/root/.local/lib/python3.6/site-packages/django/urls/conf.py", line 34, in include
    urlconf_module = import_module(urlconf_module)
  File "/usr/lib64/python3.6/importlib/__init__.py", line 126, in import_module
    return _bootstrap._gcd_import(name[level:], package, level)
  File "<frozen importlib._bootstrap>", line 994, in _gcd_import
  File "<frozen importlib._bootstrap>", line 971, in _find_and_load
  File "<frozen importlib._bootstrap>", line 955, in _find_and_load_unlocked
  File "<frozen importlib._bootstrap>", line 665, in _load_unlocked
  File "<frozen importlib._bootstrap_external>", line 678, in exec_module
  File "<frozen importlib._bootstrap>", line 219, in _call_with_frames_removed
  File "/root/aktool/main/urls.py", line 3, in <module>
    from . import views
  File "/root/aktool/main/views.py", line 209
    print("____________BBB登録完了しました" + i.id)
    ^
IndentationError: unexpected indent

Performing system checks...

Exception in thread django-main-thread:
Traceback (most recent call last):
  File "/usr/lib64/python3.6/threading.py", line 916, in _bootstrap_inner
    self.run()
  File "/usr/lib64/python3.6/threading.py", line 864, in run
    self._target(*self._args, **self._kwargs)
  File "/root/.local/lib/python3.6/site-packages/django/utils/autoreload.py", line 53, in wrapper
    fn(*args, **kwargs)
  File "/root/.local/lib/python3.6/site-packages/django/core/management/commands/runserver.py", line 117, in inner_run
    self.check(display_num_errors=True)
  File "/root/.local/lib/python3.6/site-packages/django/core/management/base.py", line 395, in check
    include_deployment_checks=include_deployment_checks,
  File "/root/.local/lib/python3.6/site-packages/django/core/management/base.py", line 382, in _run_checks
    return checks.run_checks(**kwargs)
  File "/root/.local/lib/python3.6/site-packages/django/core/checks/registry.py", line 72, in run_checks
    new_errors = check(app_configs=app_configs)
  File "/root/.local/lib/python3.6/site-packages/django/core/checks/urls.py", line 13, in check_url_config
    return check_resolver(resolver)
  File "/root/.local/lib/python3.6/site-packages/django/core/checks/urls.py", line 23, in check_resolver
    return check_method()
  File "/root/.local/lib/python3.6/site-packages/django/urls/resolvers.py", line 407, in check
    for pattern in self.url_patterns:
  File "/root/.local/lib/python3.6/site-packages/django/utils/functional.py", line 48, in __get__
    res = instance.__dict__[self.name] = self.func(instance)
  File "/root/.local/lib/python3.6/site-packages/django/urls/resolvers.py", line 588, in url_patterns
    patterns = getattr(self.urlconf_module, "urlpatterns", self.urlconf_module)
  File "/root/.local/lib/python3.6/site-packages/django/utils/functional.py", line 48, in __get__
    res = instance.__dict__[self.name] = self.func(instance)
  File "/root/.local/lib/python3.6/site-packages/django/urls/resolvers.py", line 581, in urlconf_module
    return import_module(self.urlconf_name)
  File "/usr/lib64/python3.6/importlib/__init__.py", line 126, in import_module
    return _bootstrap._gcd_import(name[level:], package, level)
  File "<frozen importlib._bootstrap>", line 994, in _gcd_import
  File "<frozen importlib._bootstrap>", line 971, in _find_and_load
  File "<frozen importlib._bootstrap>", line 955, in _find_and_load_unlocked
  File "<frozen importlib._bootstrap>", line 665, in _load_unlocked
  File "<frozen importlib._bootstrap_external>", line 678, in exec_module
  File "<frozen importlib._bootstrap>", line 219, in _call_with_frames_removed
  File "/root/aktool/amazon_scraper/urls.py", line 12, in <module>
    ] + static(settings.MEDIA_URL, document_root=settings.MEDIA_ROOT) + static(settings.STATIC_URL, document_root=settings.STATIC_ROOT)
  File "/root/.local/lib/python3.6/site-packages/django/urls/conf.py", line 34, in include
    urlconf_module = import_module(urlconf_module)
  File "/usr/lib64/python3.6/importlib/__init__.py", line 126, in import_module
    return _bootstrap._gcd_import(name[level:], package, level)
  File "<frozen importlib._bootstrap>", line 994, in _gcd_import
  File "<frozen importlib._bootstrap>", line 971, in _find_and_load
  File "<frozen importlib._bootstrap>", line 955, in _find_and_load_unlocked
  File "<frozen importlib._bootstrap>", line 665, in _load_unlocked
  File "<frozen importlib._bootstrap_external>", line 678, in exec_module
  File "<frozen importlib._bootstrap>", line 219, in _call_with_frames_removed
  File "/root/aktool/main/urls.py", line 3, in <module>
    from . import views
  File "/root/aktool/main/views.py", line 206, in <module>
    class CreateScrapeRequest(LoginRequiredMixin, TemplateView):
  File "/root/aktool/main/views.py", line 209, in CreateScrapeRequest
    print("____________BBB登録完了しました" + i.id)
NameError: name 'i' is not defined

Performing system checks...

________________scrape_request.html
________________scrape_request.html
Performing system checks...

________________scrape_request.html
____________BBB登録完了しました
System check identified no issues (0 silenced).
June 29, 2022 - 04:02:24
Django version 3.0.7, using settings 'amazon_scraper.settings'
Starting development server at http://0.0.0.0:8080/
Quit the server with CONTROL-C.
Performing system checks...

________________scrape_request.html
System check identified no issues (0 silenced).
June 29, 2022 - 04:02:33
Django version 3.0.7, using settings 'amazon_scraper.settings'
Starting development server at http://0.0.0.0:8080/
Quit the server with CONTROL-C.
Performing system checks...

________________scrape_request.html
System check identified no issues (0 silenced).
June 29, 2022 - 04:03:05
Django version 3.0.7, using settings 'amazon_scraper.settings'
Starting development server at http://0.0.0.0:8080/
Quit the server with CONTROL-C.
Exception in thread django-main-thread:
Traceback (most recent call last):
  File "/usr/lib64/python3.6/threading.py", line 916, in _bootstrap_inner
    self.run()
  File "/usr/lib64/python3.6/threading.py", line 864, in run
    self._target(*self._args, **self._kwargs)
  File "/root/.local/lib/python3.6/site-packages/django/utils/autoreload.py", line 53, in wrapper
    fn(*args, **kwargs)
  File "/root/.local/lib/python3.6/site-packages/django/core/management/commands/runserver.py", line 117, in inner_run
    self.check(display_num_errors=True)
  File "/root/.local/lib/python3.6/site-packages/django/core/management/base.py", line 395, in check
    include_deployment_checks=include_deployment_checks,
  File "/root/.local/lib/python3.6/site-packages/django/core/management/base.py", line 382, in _run_checks
    return checks.run_checks(**kwargs)
  File "/root/.local/lib/python3.6/site-packages/django/core/checks/registry.py", line 72, in run_checks
    new_errors = check(app_configs=app_configs)
  File "/root/.local/lib/python3.6/site-packages/django/core/checks/urls.py", line 13, in check_url_config
    return check_resolver(resolver)
  File "/root/.local/lib/python3.6/site-packages/django/core/checks/urls.py", line 23, in check_resolver
    return check_method()
  File "/root/.local/lib/python3.6/site-packages/django/urls/resolvers.py", line 407, in check
    for pattern in self.url_patterns:
  File "/root/.local/lib/python3.6/site-packages/django/utils/functional.py", line 48, in __get__
    res = instance.__dict__[self.name] = self.func(instance)
  File "/root/.local/lib/python3.6/site-packages/django/urls/resolvers.py", line 588, in url_patterns
    patterns = getattr(self.urlconf_module, "urlpatterns", self.urlconf_module)
  File "/root/.local/lib/python3.6/site-packages/django/utils/functional.py", line 48, in __get__
    res = instance.__dict__[self.name] = self.func(instance)
  File "/root/.local/lib/python3.6/site-packages/django/urls/resolvers.py", line 581, in urlconf_module
    return import_module(self.urlconf_name)
  File "/usr/lib64/python3.6/importlib/__init__.py", line 126, in import_module
    return _bootstrap._gcd_import(name[level:], package, level)
  File "<frozen importlib._bootstrap>", line 994, in _gcd_import
  File "<frozen importlib._bootstrap>", line 971, in _find_and_load
  File "<frozen importlib._bootstrap>", line 955, in _find_and_load_unlocked
  File "<frozen importlib._bootstrap>", line 665, in _load_unlocked
  File "<frozen importlib._bootstrap_external>", line 678, in exec_module
  File "<frozen importlib._bootstrap>", line 219, in _call_with_frames_removed
  File "/root/aktool/amazon_scraper/urls.py", line 12, in <module>
    ] + static(settings.MEDIA_URL, document_root=settings.MEDIA_ROOT) + static(settings.STATIC_URL, document_root=settings.STATIC_ROOT)
  File "/root/.local/lib/python3.6/site-packages/django/urls/conf.py", line 34, in include
    urlconf_module = import_module(urlconf_module)
  File "/usr/lib64/python3.6/importlib/__init__.py", line 126, in import_module
    return _bootstrap._gcd_import(name[level:], package, level)
  File "<frozen importlib._bootstrap>", line 994, in _gcd_import
  File "<frozen importlib._bootstrap>", line 971, in _find_and_load
  File "<frozen importlib._bootstrap>", line 955, in _find_and_load_unlocked
  File "<frozen importlib._bootstrap>", line 665, in _load_unlocked
  File "<frozen importlib._bootstrap_external>", line 678, in exec_module
  File "<frozen importlib._bootstrap>", line 219, in _call_with_frames_removed
  File "/root/aktool/main/urls.py", line 8, in <module>
    path('', views.Login.as_view(), name = 'login'),
AttributeError: module 'main.views' has no attribute 'Login'

Performing system checks...

Performing system checks...

________________scrape_request.html
System check identified no issues (0 silenced).
June 29, 2022 - 04:05:12
Django version 3.0.7, using settings 'amazon_scraper.settings'
Starting development server at http://0.0.0.0:8080/
Quit the server with CONTROL-C.
Performing system checks...

________________scrape_request.html
System check identified no issues (0 silenced).
June 29, 2022 - 04:05:27
Django version 3.0.7, using settings 'amazon_scraper.settings'
Starting development server at http://0.0.0.0:8080/
Quit the server with CONTROL-C.
Performing system checks...

________________scrape_request.html
System check identified no issues (0 silenced).
June 29, 2022 - 04:05:29
Django version 3.0.7, using settings 'amazon_scraper.settings'
Starting development server at http://0.0.0.0:8080/
Quit the server with CONTROL-C.
Performing system checks...

________________scrape_request.html
System check identified no issues (0 silenced).
June 29, 2022 - 04:06:24
Django version 3.0.7, using settings 'amazon_scraper.settings'
Starting development server at http://0.0.0.0:8080/
Quit the server with CONTROL-C.
Performing system checks...

________________scrape_request.html
System check identified no issues (0 silenced).
June 29, 2022 - 04:06:54
Django version 3.0.7, using settings 'amazon_scraper.settings'
Starting development server at http://0.0.0.0:8080/
Quit the server with CONTROL-C.
Performing system checks...

________________scrape_request.html
System check identified no issues (0 silenced).
June 29, 2022 - 04:17:44
Django version 3.0.7, using settings 'amazon_scraper.settings'
Starting development server at http://0.0.0.0:8080/
Quit the server with CONTROL-C.
Performing system checks...

________________scrape_request.html
System check identified no issues (0 silenced).
June 29, 2022 - 04:20:45
Django version 3.0.7, using settings 'amazon_scraper.settings'
Starting development server at http://0.0.0.0:8080/
Quit the server with CONTROL-C.
Performing system checks...

________________scrape_request.html
System check identified no issues (0 silenced).
June 29, 2022 - 04:20:48
Django version 3.0.7, using settings 'amazon_scraper.settings'
Starting development server at http://0.0.0.0:8080/
Quit the server with CONTROL-C.
Performing system checks...

________________scrape_request.html
System check identified no issues (0 silenced).
June 29, 2022 - 04:27:04
Django version 3.0.7, using settings 'amazon_scraper.settings'
Starting development server at http://0.0.0.0:8080/
Quit the server with CONTROL-C.
Performing system checks...

________________scrape_request.html
System check identified no issues (0 silenced).
June 29, 2022 - 04:30:14
Django version 3.0.7, using settings 'amazon_scraper.settings'
Starting development server at http://0.0.0.0:8080/
Quit the server with CONTROL-C.
Performing system checks...

________________scrape_request.html
System check identified no issues (0 silenced).
June 29, 2022 - 04:31:24
Django version 3.0.7, using settings 'amazon_scraper.settings'
Starting development server at http://0.0.0.0:8080/
Quit the server with CONTROL-C.
Performing system checks...

________________scrape_request.html
System check identified no issues (0 silenced).
June 29, 2022 - 04:33:37
Django version 3.0.7, using settings 'amazon_scraper.settings'
Starting development server at http://0.0.0.0:8080/
Quit the server with CONTROL-C.
Exception in thread django-main-thread:
Traceback (most recent call last):
  File "/root/.local/lib/python3.6/site-packages/django/apps/config.py", line 178, in get_model
    return self.models[model_name.lower()]
KeyError: 'user'

During handling of the above exception, another exception occurred:

Traceback (most recent call last):
  File "/root/.local/lib/python3.6/site-packages/django/contrib/auth/__init__.py", line 156, in get_user_model
    return django_apps.get_model(settings.AUTH_USER_MODEL, require_ready=False)
  File "/root/.local/lib/python3.6/site-packages/django/apps/registry.py", line 210, in get_model
    return app_config.get_model(model_name, require_ready=require_ready)
  File "/root/.local/lib/python3.6/site-packages/django/apps/config.py", line 181, in get_model
    "App '%s' doesn't have a '%s' model." % (self.label, model_name))
LookupError: App 'main' doesn't have a 'User' model.

During handling of the above exception, another exception occurred:

Traceback (most recent call last):
  File "/usr/lib64/python3.6/threading.py", line 916, in _bootstrap_inner
    self.run()
  File "/usr/lib64/python3.6/threading.py", line 864, in run
    self._target(*self._args, **self._kwargs)
  File "/root/.local/lib/python3.6/site-packages/django/utils/autoreload.py", line 53, in wrapper
    fn(*args, **kwargs)
  File "/root/.local/lib/python3.6/site-packages/django/core/management/commands/runserver.py", line 109, in inner_run
    autoreload.raise_last_exception()
  File "/root/.local/lib/python3.6/site-packages/django/utils/autoreload.py", line 76, in raise_last_exception
    raise _exception[1]
  File "/root/.local/lib/python3.6/site-packages/django/core/management/__init__.py", line 357, in execute
    autoreload.check_errors(django.setup)()
  File "/root/.local/lib/python3.6/site-packages/django/utils/autoreload.py", line 53, in wrapper
    fn(*args, **kwargs)
  File "/root/.local/lib/python3.6/site-packages/django/__init__.py", line 24, in setup
    apps.populate(settings.INSTALLED_APPS)
  File "/root/.local/lib/python3.6/site-packages/django/apps/registry.py", line 122, in populate
    app_config.ready()
  File "/root/.local/lib/python3.6/site-packages/django/contrib/admin/apps.py", line 24, in ready
    self.module.autodiscover()
  File "/root/.local/lib/python3.6/site-packages/django/contrib/admin/__init__.py", line 26, in autodiscover
    autodiscover_modules('admin', register_to=site)
  File "/root/.local/lib/python3.6/site-packages/django/utils/module_loading.py", line 47, in autodiscover_modules
    import_module('%s.%s' % (app_config.name, module_to_search))
  File "/usr/lib64/python3.6/importlib/__init__.py", line 126, in import_module
    return _bootstrap._gcd_import(name[level:], package, level)
  File "<frozen importlib._bootstrap>", line 994, in _gcd_import
  File "<frozen importlib._bootstrap>", line 971, in _find_and_load
  File "<frozen importlib._bootstrap>", line 955, in _find_and_load_unlocked
  File "<frozen importlib._bootstrap>", line 665, in _load_unlocked
  File "<frozen importlib._bootstrap_external>", line 678, in exec_module
  File "<frozen importlib._bootstrap>", line 219, in _call_with_frames_removed
  File "/root/.local/lib/python3.6/site-packages/django/contrib/auth/admin.py", line 6, in <module>
    from django.contrib.auth.forms import (
  File "/root/.local/lib/python3.6/site-packages/django/contrib/auth/forms.py", line 20, in <module>
    UserModel = get_user_model()
  File "/root/.local/lib/python3.6/site-packages/django/contrib/auth/__init__.py", line 161, in get_user_model
    "AUTH_USER_MODEL refers to model '%s' that has not been installed" % settings.AUTH_USER_MODEL
django.core.exceptions.ImproperlyConfigured: AUTH_USER_MODEL refers to model 'main.User' that has not been installed

Performing system checks...

________________scrape_request.html
System check identified no issues (0 silenced).
June 29, 2022 - 10:08:39
Django version 3.0.7, using settings 'amazon_scraper.settings'
Starting development server at http://0.0.0.0:8080/
Quit the server with CONTROL-C.
Performing system checks...

________________scrape_request.html
System check identified no issues (0 silenced).
July 02, 2022 - 10:41:35
Django version 3.0.7, using settings 'amazon_scraper.settings'
Starting development server at http://0.0.0.0:8080/
Quit the server with CONTROL-C.
Performing system checks...

________________scrape_request.html
System check identified no issues (0 silenced).
July 02, 2022 - 12:38:51
Django version 3.0.7, using settings 'amazon_scraper.settings'
Starting development server at http://0.0.0.0:8080/
Quit the server with CONTROL-C.
Performing system checks...

________________scrape_request.html
System check identified no issues (0 silenced).
July 02, 2022 - 12:40:53
Django version 3.0.7, using settings 'amazon_scraper.settings'
Starting development server at http://0.0.0.0:8080/
Quit the server with CONTROL-C.
Performing system checks...

________________scrape_request.html
System check identified no issues (0 silenced).
July 02, 2022 - 12:42:56
Django version 3.0.7, using settings 'amazon_scraper.settings'
Starting development server at http://0.0.0.0:8080/
Quit the server with CONTROL-C.
Exception in thread django-main-thread:
Traceback (most recent call last):
  File "/usr/lib64/python3.6/threading.py", line 916, in _bootstrap_inner
    self.run()
  File "/usr/lib64/python3.6/threading.py", line 864, in run
    self._target(*self._args, **self._kwargs)
  File "/root/.local/lib/python3.6/site-packages/django/utils/autoreload.py", line 53, in wrapper
    fn(*args, **kwargs)
  File "/root/.local/lib/python3.6/site-packages/django/core/management/commands/runserver.py", line 117, in inner_run
    self.check(display_num_errors=True)
  File "/root/.local/lib/python3.6/site-packages/django/core/management/base.py", line 395, in check
    include_deployment_checks=include_deployment_checks,
  File "/root/.local/lib/python3.6/site-packages/django/core/management/base.py", line 382, in _run_checks
    return checks.run_checks(**kwargs)
  File "/root/.local/lib/python3.6/site-packages/django/core/checks/registry.py", line 72, in run_checks
    new_errors = check(app_configs=app_configs)
  File "/root/.local/lib/python3.6/site-packages/django/core/checks/urls.py", line 13, in check_url_config
    return check_resolver(resolver)
  File "/root/.local/lib/python3.6/site-packages/django/core/checks/urls.py", line 23, in check_resolver
    return check_method()
  File "/root/.local/lib/python3.6/site-packages/django/urls/resolvers.py", line 407, in check
    for pattern in self.url_patterns:
  File "/root/.local/lib/python3.6/site-packages/django/utils/functional.py", line 48, in __get__
    res = instance.__dict__[self.name] = self.func(instance)
  File "/root/.local/lib/python3.6/site-packages/django/urls/resolvers.py", line 588, in url_patterns
    patterns = getattr(self.urlconf_module, "urlpatterns", self.urlconf_module)
  File "/root/.local/lib/python3.6/site-packages/django/utils/functional.py", line 48, in __get__
    res = instance.__dict__[self.name] = self.func(instance)
  File "/root/.local/lib/python3.6/site-packages/django/urls/resolvers.py", line 581, in urlconf_module
    return import_module(self.urlconf_name)
  File "/usr/lib64/python3.6/importlib/__init__.py", line 126, in import_module
    return _bootstrap._gcd_import(name[level:], package, level)
  File "<frozen importlib._bootstrap>", line 994, in _gcd_import
  File "<frozen importlib._bootstrap>", line 971, in _find_and_load
  File "<frozen importlib._bootstrap>", line 955, in _find_and_load_unlocked
  File "<frozen importlib._bootstrap>", line 665, in _load_unlocked
  File "<frozen importlib._bootstrap_external>", line 678, in exec_module
  File "<frozen importlib._bootstrap>", line 219, in _call_with_frames_removed
  File "/root/aktool/amazon_scraper/urls.py", line 12, in <module>
    ] + static(settings.MEDIA_URL, document_root=settings.MEDIA_ROOT) + static(settings.STATIC_URL, document_root=settings.STATIC_ROOT)
  File "/root/.local/lib/python3.6/site-packages/django/urls/conf.py", line 34, in include
    urlconf_module = import_module(urlconf_module)
  File "/usr/lib64/python3.6/importlib/__init__.py", line 126, in import_module
    return _bootstrap._gcd_import(name[level:], package, level)
  File "<frozen importlib._bootstrap>", line 994, in _gcd_import
  File "<frozen importlib._bootstrap>", line 971, in _find_and_load
  File "<frozen importlib._bootstrap>", line 955, in _find_and_load_unlocked
  File "<frozen importlib._bootstrap>", line 665, in _load_unlocked
  File "<frozen importlib._bootstrap_external>", line 678, in exec_module
  File "<frozen importlib._bootstrap>", line 219, in _call_with_frames_removed
  File "/root/aktool/main/urls.py", line 8, in <module>
    path('', views.Login.as_view(), name = 'login'),
AttributeError: module 'main.views' has no attribute 'Login'

Performing system checks...

Performing system checks...

________________scrape_request.html
System check identified no issues (0 silenced).
July 02, 2022 - 12:43:20
Django version 3.0.7, using settings 'amazon_scraper.settings'
Starting development server at http://0.0.0.0:8080/
Quit the server with CONTROL-C.
Performing system checks...

________________scrape_request.html
System check identified no issues (0 silenced).
July 02, 2022 - 12:44:33
Django version 3.0.7, using settings 'amazon_scraper.settings'
Starting development server at http://0.0.0.0:8080/
Quit the server with CONTROL-C.
Performing system checks...

________________scrape_request.html
System check identified no issues (0 silenced).
July 02, 2022 - 12:44:35
Django version 3.0.7, using settings 'amazon_scraper.settings'
Starting development server at http://0.0.0.0:8080/
Quit the server with CONTROL-C.
Performing system checks...

________________scrape_request.html
System check identified no issues (0 silenced).
July 02, 2022 - 12:45:40
Django version 3.0.7, using settings 'amazon_scraper.settings'
Starting development server at http://0.0.0.0:8080/
Quit the server with CONTROL-C.
Performing system checks...

________________scrape_request.html
System check identified no issues (0 silenced).
July 02, 2022 - 12:45:53
Django version 3.0.7, using settings 'amazon_scraper.settings'
Starting development server at http://0.0.0.0:8080/
Quit the server with CONTROL-C.
Performing system checks...

________________scrape_request.html
System check identified no issues (0 silenced).
July 02, 2022 - 12:47:00
Django version 3.0.7, using settings 'amazon_scraper.settings'
Starting development server at http://0.0.0.0:8080/
Quit the server with CONTROL-C.
Performing system checks...

________________scrape_request.html
System check identified no issues (0 silenced).
July 02, 2022 - 12:50:00
Django version 3.0.7, using settings 'amazon_scraper.settings'
Starting development server at http://0.0.0.0:8080/
Quit the server with CONTROL-C.
Performing system checks...

________________scrape_request.html
System check identified no issues (0 silenced).
July 02, 2022 - 12:50:12
Django version 3.0.7, using settings 'amazon_scraper.settings'
Starting development server at http://0.0.0.0:8080/
Quit the server with CONTROL-C.
ScrapeRequestScrapeRequestScrapeRequestScrapeRequest
Performing system checks...

________________scrape_request.html
System check identified no issues (0 silenced).
July 02, 2022 - 13:01:30
Django version 3.0.7, using settings 'amazon_scraper.settings'
Starting development server at http://0.0.0.0:8080/
Quit the server with CONTROL-C.
Performing system checks...

________________scrape_request.html
System check identified no issues (0 silenced).
July 02, 2022 - 13:02:21
Django version 3.0.7, using settings 'amazon_scraper.settings'
Starting development server at http://0.0.0.0:8080/
Quit the server with CONTROL-C.
Performing system checks...

________________scrape_request.html
System check identified no issues (0 silenced).
July 02, 2022 - 13:08:09
Django version 3.0.7, using settings 'amazon_scraper.settings'
Starting development server at http://0.0.0.0:8080/
Quit the server with CONTROL-C.
Performing system checks...

________________scrape_request.html
System check identified no issues (0 silenced).
July 02, 2022 - 13:08:11
Django version 3.0.7, using settings 'amazon_scraper.settings'
Starting development server at http://0.0.0.0:8080/
Quit the server with CONTROL-C.
Performing system checks...

________________scrape_request.html
System check identified no issues (0 silenced).
July 02, 2022 - 13:09:43
Django version 3.0.7, using settings 'amazon_scraper.settings'
Starting development server at http://0.0.0.0:8080/
Quit the server with CONTROL-C.
Exception in thread django-main-thread:
Traceback (most recent call last):
  File "/root/.local/lib/python3.6/site-packages/django/apps/config.py", line 178, in get_model
    return self.models[model_name.lower()]
KeyError: 'user'

During handling of the above exception, another exception occurred:

Traceback (most recent call last):
  File "/root/.local/lib/python3.6/site-packages/django/contrib/auth/__init__.py", line 156, in get_user_model
    return django_apps.get_model(settings.AUTH_USER_MODEL, require_ready=False)
  File "/root/.local/lib/python3.6/site-packages/django/apps/registry.py", line 210, in get_model
    return app_config.get_model(model_name, require_ready=require_ready)
  File "/root/.local/lib/python3.6/site-packages/django/apps/config.py", line 181, in get_model
    "App '%s' doesn't have a '%s' model." % (self.label, model_name))
LookupError: App 'main' doesn't have a 'User' model.

During handling of the above exception, another exception occurred:

Traceback (most recent call last):
  File "/usr/lib64/python3.6/threading.py", line 916, in _bootstrap_inner
    self.run()
  File "/usr/lib64/python3.6/threading.py", line 864, in run
    self._target(*self._args, **self._kwargs)
  File "/root/.local/lib/python3.6/site-packages/django/utils/autoreload.py", line 53, in wrapper
    fn(*args, **kwargs)
  File "/root/.local/lib/python3.6/site-packages/django/core/management/commands/runserver.py", line 109, in inner_run
    autoreload.raise_last_exception()
  File "/root/.local/lib/python3.6/site-packages/django/utils/autoreload.py", line 76, in raise_last_exception
    raise _exception[1]
  File "/root/.local/lib/python3.6/site-packages/django/core/management/__init__.py", line 357, in execute
    autoreload.check_errors(django.setup)()
  File "/root/.local/lib/python3.6/site-packages/django/utils/autoreload.py", line 53, in wrapper
    fn(*args, **kwargs)
  File "/root/.local/lib/python3.6/site-packages/django/__init__.py", line 24, in setup
    apps.populate(settings.INSTALLED_APPS)
  File "/root/.local/lib/python3.6/site-packages/django/apps/registry.py", line 122, in populate
    app_config.ready()
  File "/root/.local/lib/python3.6/site-packages/django/contrib/admin/apps.py", line 24, in ready
    self.module.autodiscover()
  File "/root/.local/lib/python3.6/site-packages/django/contrib/admin/__init__.py", line 26, in autodiscover
    autodiscover_modules('admin', register_to=site)
  File "/root/.local/lib/python3.6/site-packages/django/utils/module_loading.py", line 47, in autodiscover_modules
    import_module('%s.%s' % (app_config.name, module_to_search))
  File "/usr/lib64/python3.6/importlib/__init__.py", line 126, in import_module
    return _bootstrap._gcd_import(name[level:], package, level)
  File "<frozen importlib._bootstrap>", line 994, in _gcd_import
  File "<frozen importlib._bootstrap>", line 971, in _find_and_load
  File "<frozen importlib._bootstrap>", line 955, in _find_and_load_unlocked
  File "<frozen importlib._bootstrap>", line 665, in _load_unlocked
  File "<frozen importlib._bootstrap_external>", line 678, in exec_module
  File "<frozen importlib._bootstrap>", line 219, in _call_with_frames_removed
  File "/root/.local/lib/python3.6/site-packages/django/contrib/auth/admin.py", line 6, in <module>
    from django.contrib.auth.forms import (
  File "/root/.local/lib/python3.6/site-packages/django/contrib/auth/forms.py", line 20, in <module>
    UserModel = get_user_model()
  File "/root/.local/lib/python3.6/site-packages/django/contrib/auth/__init__.py", line 161, in get_user_model
    "AUTH_USER_MODEL refers to model '%s' that has not been installed" % settings.AUTH_USER_MODEL
django.core.exceptions.ImproperlyConfigured: AUTH_USER_MODEL refers to model 'main.User' that has not been installed

Performing system checks...

________________scrape_request.html
System check identified no issues (0 silenced).
July 02, 2022 - 14:03:16
Django version 3.0.7, using settings 'amazon_scraper.settings'
Starting development server at http://0.0.0.0:8080/
Quit the server with CONTROL-C.
